2023-10-14 22:41:00,575 INFO    StreamThr :1770712 [internal.py:wandb_internal():86] W&B internal server running at pid: 1770712, started at: 2023-10-14 22:41:00.575452
2023-10-14 22:41:00,576 DEBUG   HandlerThread:1770712 [handler.py:handle_request():144] handle_request: status
2023-10-14 22:41:00,577 INFO    WriterThread:1770712 [datastore.py:open_for_write():85] open: /home/sujaynair/RaCA-SOC-a-spectrum-analysis/RaCA-SOC-a/Step9/wandb/run-20231014_224100-7n65rusr/run-7n65rusr.wandb
2023-10-14 22:41:00,578 DEBUG   SenderThread:1770712 [sender.py:send():379] send: header
2023-10-14 22:41:00,579 DEBUG   SenderThread:1770712 [sender.py:send():379] send: run
2023-10-14 22:41:05,580 DEBUG   HandlerThread:1770712 [handler.py:handle_request():144] handle_request: keepalive
2023-10-14 22:41:10,581 DEBUG   HandlerThread:1770712 [handler.py:handle_request():144] handle_request: keepalive
2023-10-14 22:41:15,582 DEBUG   HandlerThread:1770712 [handler.py:handle_request():144] handle_request: keepalive
2023-10-14 22:41:20,583 DEBUG   HandlerThread:1770712 [handler.py:handle_request():144] handle_request: keepalive
2023-10-14 22:41:25,584 DEBUG   HandlerThread:1770712 [handler.py:handle_request():144] handle_request: keepalive
2023-10-14 22:41:30,586 DEBUG   HandlerThread:1770712 [handler.py:handle_request():144] handle_request: keepalive
2023-10-14 22:41:35,587 DEBUG   HandlerThread:1770712 [handler.py:handle_request():144] handle_request: keepalive
2023-10-14 22:41:40,588 DEBUG   HandlerThread:1770712 [handler.py:handle_request():144] handle_request: keepalive
2023-10-14 22:41:45,590 DEBUG   HandlerThread:1770712 [handler.py:handle_request():144] handle_request: keepalive
2023-10-14 22:41:50,591 DEBUG   HandlerThread:1770712 [handler.py:handle_request():144] handle_request: keepalive
2023-10-14 22:41:55,592 DEBUG   HandlerThread:1770712 [handler.py:handle_request():144] handle_request: keepalive
2023-10-14 22:42:00,593 DEBUG   HandlerThread:1770712 [handler.py:handle_request():144] handle_request: keepalive
2023-10-14 22:42:04,304 INFO    SenderThread:1770712 [retry.py:__call__():172] Retry attempt failed:
Traceback (most recent call last):
  File "/home/sujaynair/.local/lib/python3.10/site-packages/urllib3/connectionpool.py", line 536, in _make_request
    response = conn.getresponse()
  File "/home/sujaynair/.local/lib/python3.10/site-packages/urllib3/connection.py", line 461, in getresponse
    httplib_response = super().getresponse()
  File "/usr/lib/python3.10/http/client.py", line 1375, in getresponse
    response.begin()
  File "/usr/lib/python3.10/http/client.py", line 318, in begin
    version, status, reason = self._read_status()
  File "/usr/lib/python3.10/http/client.py", line 279, in _read_status
    line = str(self.fp.readline(_MAXLINE + 1), "iso-8859-1")
  File "/usr/lib/python3.10/socket.py", line 705, in readinto
    return self._sock.recv_into(b)
  File "/usr/lib/python3.10/ssl.py", line 1274, in recv_into
    return self.read(nbytes, buffer)
  File "/usr/lib/python3.10/ssl.py", line 1130, in read
    return self._sslobj.read(len, buffer)
TimeoutError: The read operation timed out

The above exception was the direct cause of the following exception:

Traceback (most recent call last):
  File "/home/sujaynair/.local/lib/python3.10/site-packages/requests/adapters.py", line 486, in send
    resp = conn.urlopen(
  File "/home/sujaynair/.local/lib/python3.10/site-packages/urllib3/connectionpool.py", line 844, in urlopen
    retries = retries.increment(
  File "/home/sujaynair/.local/lib/python3.10/site-packages/urllib3/util/retry.py", line 470, in increment
    raise reraise(type(error), error, _stacktrace)
  File "/home/sujaynair/.local/lib/python3.10/site-packages/urllib3/util/util.py", line 39, in reraise
    raise value
  File "/home/sujaynair/.local/lib/python3.10/site-packages/urllib3/connectionpool.py", line 790, in urlopen
    response = self._make_request(
  File "/home/sujaynair/.local/lib/python3.10/site-packages/urllib3/connectionpool.py", line 538, in _make_request
    self._raise_timeout(err=e, url=url, timeout_value=read_timeout)
  File "/home/sujaynair/.local/lib/python3.10/site-packages/urllib3/connectionpool.py", line 370, in _raise_timeout
    raise ReadTimeoutError(
urllib3.exceptions.ReadTimeoutError: HTTPSConnectionPool(host='api.wandb.ai', port=443): Read timed out. (read timeout=20)

During handling of the above exception, another exception occurred:

Traceback (most recent call last):
  File "/home/sujaynair/.local/lib/python3.10/site-packages/wandb/sdk/lib/retry.py", line 131, in __call__
    result = self._call_fn(*args, **kwargs)
  File "/home/sujaynair/.local/lib/python3.10/site-packages/wandb/sdk/internal/internal_api.py", line 358, in execute
    return self.client.execute(*args, **kwargs)  # type: ignore
  File "/home/sujaynair/.local/lib/python3.10/site-packages/wandb/vendor/gql-0.2.0/wandb_gql/client.py", line 52, in execute
    result = self._get_result(document, *args, **kwargs)
  File "/home/sujaynair/.local/lib/python3.10/site-packages/wandb/vendor/gql-0.2.0/wandb_gql/client.py", line 60, in _get_result
    return self.transport.execute(document, *args, **kwargs)
  File "/home/sujaynair/.local/lib/python3.10/site-packages/wandb/sdk/lib/gql_request.py", line 55, in execute
    request = self.session.post(self.url, **post_args)
  File "/home/sujaynair/.local/lib/python3.10/site-packages/requests/sessions.py", line 637, in post
    return self.request("POST", url, data=data, json=json, **kwargs)
  File "/home/sujaynair/.local/lib/python3.10/site-packages/requests/sessions.py", line 589, in request
    resp = self.send(prep, **send_kwargs)
  File "/home/sujaynair/.local/lib/python3.10/site-packages/requests/sessions.py", line 703, in send
    r = adapter.send(request, **kwargs)
  File "/home/sujaynair/.local/lib/python3.10/site-packages/requests/adapters.py", line 532, in send
    raise ReadTimeout(e, request=request)
requests.exceptions.ReadTimeout: HTTPSConnectionPool(host='api.wandb.ai', port=443): Read timed out. (read timeout=20)
2023-10-14 22:42:05,594 DEBUG   HandlerThread:1770712 [handler.py:handle_request():144] handle_request: keepalive
2023-10-14 22:42:10,595 DEBUG   HandlerThread:1770712 [handler.py:handle_request():144] handle_request: keepalive
2023-10-14 22:42:15,596 DEBUG   HandlerThread:1770712 [handler.py:handle_request():144] handle_request: keepalive
2023-10-14 22:42:20,597 DEBUG   HandlerThread:1770712 [handler.py:handle_request():144] handle_request: keepalive
2023-10-14 22:42:25,598 DEBUG   HandlerThread:1770712 [handler.py:handle_request():144] handle_request: keepalive
2023-10-14 22:42:30,600 DEBUG   HandlerThread:1770712 [handler.py:handle_request():144] handle_request: cancel
2023-10-14 22:42:30,609 DEBUG   HandlerThread:1770712 [handler.py:handle_request():144] handle_request: cancel
2023-10-14 22:42:30,609 DEBUG   SenderThread:1770712 [sender.py:send():388] Record cancelled: run
2023-10-14 22:42:30,609 DEBUG   HandlerThread:1770712 [handler.py:handle_request():144] handle_request: status_report
2023-10-14 22:42:30,796 DEBUG   HandlerThread:1770712 [handler.py:handle_request():144] handle_request: shutdown
2023-10-14 22:42:30,796 INFO    HandlerThread:1770712 [handler.py:finish():840] shutting down handler
2023-10-14 22:42:31,609 INFO    SenderThread:1770712 [sender.py:finish():1531] shutting down sender
2023-10-14 22:42:31,610 INFO    WriterThread:1770712 [datastore.py:close():294] close: /home/sujaynair/RaCA-SOC-a-spectrum-analysis/RaCA-SOC-a/Step9/wandb/run-20231014_224100-7n65rusr/run-7n65rusr.wandb
